[2025-07-07T20:21:41.518+0000] {taskinstance.py:1956} INFO - Dependencies all met for dep_context=non-requeueable deps ti=<TaskInstance: pipeline_dbt.dbt_run manual__2025-07-07T20:21:40.192141+00:00 [queued]>
[2025-07-07T20:21:41.530+0000] {taskinstance.py:1956} INFO - Dependencies all met for dep_context=requeueable deps ti=<TaskInstance: pipeline_dbt.dbt_run manual__2025-07-07T20:21:40.192141+00:00 [queued]>
[2025-07-07T20:21:41.531+0000] {taskinstance.py:2170} INFO - Starting attempt 1 of 2
[2025-07-07T20:21:41.554+0000] {taskinstance.py:2191} INFO - Executing <Task(BashOperator): dbt_run> on 2025-07-07 20:21:40.192141+00:00
[2025-07-07T20:21:41.558+0000] {standard_task_runner.py:60} INFO - Started process 194 to run task
[2025-07-07T20:21:41.562+0000] {standard_task_runner.py:87} INFO - Running: ['airflow', 'tasks', 'run', 'pipeline_dbt', 'dbt_run', 'manual__2025-07-07T20:21:40.192141+00:00', '--job-id', '2', '--raw', '--subdir', 'DAGS_FOLDER/pipeline_dbt.py', '--cfg-path', '/tmp/tmperepqej0']
[2025-07-07T20:21:41.564+0000] {standard_task_runner.py:88} INFO - Job 2: Subtask dbt_run
[2025-07-07T20:21:41.588+0000] {logging_mixin.py:188} WARNING - /home/airflow/.local/lib/python3.8/site-packages/airflow/settings.py:194 DeprecationWarning: The sql_alchemy_conn option in [core] has been moved to the sql_alchemy_conn option in [database] - the old setting has been used, but please update your config.
[2025-07-07T20:21:41.633+0000] {task_command.py:423} INFO - Running <TaskInstance: pipeline_dbt.dbt_run manual__2025-07-07T20:21:40.192141+00:00 [running]> on host 2b2bfc5ff213
[2025-07-07T20:21:41.728+0000] {taskinstance.py:2480} INFO - Exporting env vars: AIRFLOW_CTX_DAG_OWNER='airflow' AIRFLOW_CTX_DAG_ID='pipeline_dbt' AIRFLOW_CTX_TASK_ID='dbt_run' AIRFLOW_CTX_EXECUTION_DATE='2025-07-07T20:21:40.192141+00:00' AIRFLOW_CTX_TRY_NUMBER='1' AIRFLOW_CTX_DAG_RUN_ID='manual__2025-07-07T20:21:40.192141+00:00'
[2025-07-07T20:21:41.729+0000] {subprocess.py:63} INFO - Tmp dir root location: /tmp
[2025-07-07T20:21:41.730+0000] {subprocess.py:75} INFO - Running command: ['/usr/bin/bash', '-c', 'docker exec dbt dbt run']
[2025-07-07T20:21:41.740+0000] {subprocess.py:86} INFO - Output:
[2025-07-07T20:21:41.930+0000] {subprocess.py:93} INFO - Cannot connect to the Docker daemon at unix:///var/run/docker.sock. Is the docker daemon running?
[2025-07-07T20:21:41.932+0000] {subprocess.py:97} INFO - Command exited with return code 1
[2025-07-07T20:21:41.945+0000] {taskinstance.py:2698} ERROR - Task failed with exception
Traceback (most recent call last):
  File "/home/airflow/.local/lib/python3.8/site-packages/airflow/models/taskinstance.py", line 433, in _execute_task
    result = execute_callable(context=context, **execute_callable_kwargs)
  File "/home/airflow/.local/lib/python3.8/site-packages/airflow/operators/bash.py", line 212, in execute
    raise AirflowException(
airflow.exceptions.AirflowException: Bash command failed. The command returned a non-zero exit code 1.
[2025-07-07T20:21:41.948+0000] {taskinstance.py:1138} INFO - Marking task as UP_FOR_RETRY. dag_id=pipeline_dbt, task_id=dbt_run, execution_date=20250707T202140, start_date=20250707T202141, end_date=20250707T202141
[2025-07-07T20:21:41.960+0000] {standard_task_runner.py:107} ERROR - Failed to execute job 2 for task dbt_run (Bash command failed. The command returned a non-zero exit code 1.; 194)
[2025-07-07T20:21:41.979+0000] {local_task_job_runner.py:234} INFO - Task exited with return code 1
[2025-07-07T20:21:42.012+0000] {taskinstance.py:3280} INFO - 0 downstream tasks scheduled from follow-on schedule check
